{
  "dataset": "banking",
  "description_number": 3,
  "timestamp": "20250828_190549",
  "generated_types": [
    {
      "resultType": "error",
      "explanation": "HTTPConnectionPool(host='localhost', port=8083): Max retries exceeded with url: /api/semantic-types/generate (Caused by NewConnectionError('<urllib3.connection.HTTPConnection object at 0x1288df250>: Failed to establish a new connection: [Errno 61] Connection refused'))",
      "semanticType": "BranchID"
    },
    {
      "resultType": "error",
      "explanation": "HTTPConnectionPool(host='localhost', port=8083): Max retries exceeded with url: /api/semantic-types/generate (Caused by NewConnectionError('<urllib3.connection.HTTPConnection object at 0x1288dd360>: Failed to establish a new connection: [Errno 61] Connection refused'))",
      "semanticType": "FeedbackID"
    },
    {
      "resultType": "error",
      "explanation": "HTTPConnectionPool(host='localhost', port=8083): Max retries exceeded with url: /api/semantic-types/generate (Caused by NewConnectionError('<urllib3.connection.HTTPConnection object at 0x1288de110>: Failed to establish a new connection: [Errno 61] Connection refused'))",
      "semanticType": "LoanStatus"
    },
    {
      "resultType": "error",
      "explanation": "HTTPConnectionPool(host='localhost', port=8083): Max retries exceeded with url: /api/semantic-types/generate (Caused by NewConnectionError('<urllib3.connection.HTTPConnection object at 0x1288dffd0>: Failed to establish a new connection: [Errno 61] Connection refused'))",
      "semanticType": "InterestRate"
    },
    {
      "resultType": "error",
      "explanation": "HTTPConnectionPool(host='localhost', port=8083): Max retries exceeded with url: /api/semantic-types/generate (Caused by NewConnectionError('<urllib3.connection.HTTPConnection object at 0x12891ebf0>: Failed to establish a new connection: [Errno 61] Connection refused'))",
      "semanticType": "ResolutionStatus"
    },
    {
      "resultType": "error",
      "explanation": "HTTPConnectionPool(host='localhost', port=8083): Max retries exceeded with url: /api/semantic-types/generate (Caused by NewConnectionError('<urllib3.connection.HTTPConnection object at 0x1288debf0>: Failed to establish a new connection: [Errno 61] Connection refused'))",
      "semanticType": "LoanType"
    },
    {
      "resultType": "error",
      "explanation": "HTTPConnectionPool(host='localhost', port=8083): Max retries exceeded with url: /api/semantic-types/generate (Caused by NewConnectionError('<urllib3.connection.HTTPConnection object at 0x12891d1e0>: Failed to establish a new connection: [Errno 61] Connection refused'))",
      "semanticType": "CardType"
    },
    {
      "resultType": "error",
      "explanation": "HTTPConnectionPool(host='localhost', port=8083): Max retries exceeded with url: /api/semantic-types/generate (Caused by NewConnectionError('<urllib3.connection.HTTPConnection object at 0x12891f730>: Failed to establish a new connection: [Errno 61] Connection refused'))",
      "semanticType": "FeedbackType"
    },
    {
      "resultType": "error",
      "explanation": "HTTPConnectionPool(host='localhost', port=8083): Max retries exceeded with url: /api/semantic-types/generate (Caused by NewConnectionError('<urllib3.connection.HTTPConnection object at 0x12891d5a0>: Failed to establish a new connection: [Errno 61] Connection refused'))",
      "semanticType": "TransactionID"
    },
    {
      "resultType": "error",
      "explanation": "HTTPConnectionPool(host='localhost', port=8083): Max retries exceeded with url: /api/semantic-types/generate (Caused by NewConnectionError('<urllib3.connection.HTTPConnection object at 0x12891e4d0>: Failed to establish a new connection: [Errno 61] Connection refused'))",
      "semanticType": "TransactionAmount"
    },
    {
      "resultType": "error",
      "explanation": "HTTPConnectionPool(host='localhost', port=8083): Max retries exceeded with url: /api/semantic-types/generate (Caused by NewConnectionError('<urllib3.connection.HTTPConnection object at 0x12891f370>: Failed to establish a new connection: [Errno 61] Connection refused'))",
      "semanticType": "LoanID"
    },
    {
      "resultType": "error",
      "explanation": "HTTPConnectionPool(host='localhost', port=8083): Max retries exceeded with url: /api/semantic-types/generate (Caused by NewConnectionError('<urllib3.connection.HTTPConnection object at 0x1226d1ed0>: Failed to establish a new connection: [Errno 61] Connection refused'))",
      "semanticType": "AccountOpeningDate"
    },
    {
      "resultType": "error",
      "explanation": "HTTPConnectionPool(host='localhost', port=8083): Max retries exceeded with url: /api/semantic-types/generate (Caused by NewConnectionError('<urllib3.connection.HTTPConnection object at 0x1288dcb50>: Failed to establish a new connection: [Errno 61] Connection refused'))",
      "semanticType": "TransactionDate"
    },
    {
      "resultType": "error",
      "explanation": "HTTPConnectionPool(host='localhost', port=8083): Max retries exceeded with url: /api/semantic-types/generate (Caused by NewConnectionError('<urllib3.connection.HTTPConnection object at 0x12891ce20>: Failed to establish a new connection: [Errno 61] Connection refused'))",
      "semanticType": "LoanAmount"
    },
    {
      "resultType": "error",
      "explanation": "HTTPConnectionPool(host='localhost', port=8083): Max retries exceeded with url: /api/semantic-types/generate (Caused by NewConnectionError('<urllib3.connection.HTTPConnection object at 0x128818cd0>: Failed to establish a new connection: [Errno 61] Connection refused'))",
      "semanticType": "AccountBalance"
    },
    {
      "resultType": "error",
      "explanation": "HTTPConnectionPool(host='localhost', port=8083): Max retries exceeded with url: /api/semantic-types/generate (Caused by NewConnectionError('<urllib3.connection.HTTPConnection object at 0x1288df5b0>: Failed to establish a new connection: [Errno 61] Connection refused'))",
      "semanticType": "CreditLimit"
    },
    {
      "resultType": "error",
      "explanation": "HTTPConnectionPool(host='localhost', port=8083): Max retries exceeded with url: /api/semantic-types/generate (Caused by NewConnectionError('<urllib3.connection.HTTPConnection object at 0x1288b7eb0>: Failed to establish a new connection: [Errno 61] Connection refused'))",
      "semanticType": "AccountType"
    },
    {
      "resultType": "error",
      "explanation": "HTTPConnectionPool(host='localhost', port=8083): Max retries exceeded with url: /api/semantic-types/generate (Caused by NewConnectionError('<urllib3.connection.HTTPConnection object at 0x12881b490>: Failed to establish a new connection: [Errno 61] Connection refused'))",
      "semanticType": "AccountBalanceAfterTransaction"
    }
  ]
}