{
  "dataset": "banking",
  "description_number": 6,
  "timestamp": "20250828_190549",
  "generated_types": [
    {
      "resultType": "error",
      "explanation": "HTTPConnectionPool(host='localhost', port=8083): Max retries exceeded with url: /api/semantic-types/generate (Caused by NewConnectionError('<urllib3.connection.HTTPConnection object at 0x128966050>: Failed to establish a new connection: [Errno 61] Connection refused'))",
      "semanticType": "AccountType"
    },
    {
      "resultType": "error",
      "explanation": "HTTPConnectionPool(host='localhost', port=8083): Max retries exceeded with url: /api/semantic-types/generate (Caused by NewConnectionError('<urllib3.connection.HTTPConnection object at 0x12891e050>: Failed to establish a new connection: [Errno 61] Connection refused'))",
      "semanticType": "TransactionDate"
    },
    {
      "resultType": "error",
      "explanation": "HTTPConnectionPool(host='localhost', port=8083): Max retries exceeded with url: /api/semantic-types/generate (Caused by NewConnectionError('<urllib3.connection.HTTPConnection object at 0x12891f6a0>: Failed to establish a new connection: [Errno 61] Connection refused'))",
      "semanticType": "AccountBalanceAfterTransaction"
    },
    {
      "resultType": "error",
      "explanation": "HTTPConnectionPool(host='localhost', port=8083): Max retries exceeded with url: /api/semantic-types/generate (Caused by NewConnectionError('<urllib3.connection.HTTPConnection object at 0x1288b4e50>: Failed to establish a new connection: [Errno 61] Connection refused'))",
      "semanticType": "AccountOpeningDate"
    },
    {
      "resultType": "error",
      "explanation": "HTTPConnectionPool(host='localhost', port=8083): Max retries exceeded with url: /api/semantic-types/generate (Caused by NewConnectionError('<urllib3.connection.HTTPConnection object at 0x12891f250>: Failed to establish a new connection: [Errno 61] Connection refused'))",
      "semanticType": "BranchID"
    },
    {
      "resultType": "error",
      "explanation": "HTTPConnectionPool(host='localhost', port=8083): Max retries exceeded with url: /api/semantic-types/generate (Caused by NewConnectionError('<urllib3.connection.HTTPConnection object at 0x1289654b0>: Failed to establish a new connection: [Errno 61] Connection refused'))",
      "semanticType": "TransactionAmount"
    },
    {
      "resultType": "error",
      "explanation": "HTTPConnectionPool(host='localhost', port=8083): Max retries exceeded with url: /api/semantic-types/generate (Caused by NewConnectionError('<urllib3.connection.HTTPConnection object at 0x1288b4f70>: Failed to establish a new connection: [Errno 61] Connection refused'))",
      "semanticType": "AccountBalance"
    },
    {
      "resultType": "error",
      "explanation": "HTTPConnectionPool(host='localhost', port=8083): Max retries exceeded with url: /api/semantic-types/generate (Caused by NewConnectionError('<urllib3.connection.HTTPConnection object at 0x12891ccd0>: Failed to establish a new connection: [Errno 61] Connection refused'))",
      "semanticType": "TransactionID"
    },
    {
      "resultType": "error",
      "explanation": "HTTPConnectionPool(host='localhost', port=8083): Max retries exceeded with url: /api/semantic-types/generate (Caused by NewConnectionError('<urllib3.connection.HTTPConnection object at 0x122745930>: Failed to establish a new connection: [Errno 61] Connection refused'))",
      "semanticType": "LoanID"
    },
    {
      "resultType": "error",
      "explanation": "HTTPConnectionPool(host='localhost', port=8083): Max retries exceeded with url: /api/semantic-types/generate (Caused by NewConnectionError('<urllib3.connection.HTTPConnection object at 0x1288b5d50>: Failed to establish a new connection: [Errno 61] Connection refused'))",
      "semanticType": "CreditLimit"
    },
    {
      "resultType": "error",
      "explanation": "HTTPConnectionPool(host='localhost', port=8083): Max retries exceeded with url: /api/semantic-types/generate (Caused by NewConnectionError('<urllib3.connection.HTTPConnection object at 0x1288b7ca0>: Failed to establish a new connection: [Errno 61] Connection refused'))",
      "semanticType": "LoanStatus"
    },
    {
      "resultType": "error",
      "explanation": "HTTPConnectionPool(host='localhost', port=8083): Max retries exceeded with url: /api/semantic-types/generate (Caused by NewConnectionError('<urllib3.connection.HTTPConnection object at 0x12264e980>: Failed to establish a new connection: [Errno 61] Connection refused'))",
      "semanticType": "LoanAmount"
    },
    {
      "resultType": "error",
      "explanation": "HTTPConnectionPool(host='localhost', port=8083): Max retries exceeded with url: /api/semantic-types/generate (Caused by NewConnectionError('<urllib3.connection.HTTPConnection object at 0x1226d1bd0>: Failed to establish a new connection: [Errno 61] Connection refused'))",
      "semanticType": "FeedbackID"
    },
    {
      "resultType": "error",
      "explanation": "HTTPConnectionPool(host='localhost', port=8083): Max retries exceeded with url: /api/semantic-types/generate (Caused by NewConnectionError('<urllib3.connection.HTTPConnection object at 0x1226d00d0>: Failed to establish a new connection: [Errno 61] Connection refused'))",
      "semanticType": "CardType"
    },
    {
      "resultType": "error",
      "explanation": "HTTPConnectionPool(host='localhost', port=8083): Max retries exceeded with url: /api/semantic-types/generate (Caused by NewConnectionError('<urllib3.connection.HTTPConnection object at 0x1226d0820>: Failed to establish a new connection: [Errno 61] Connection refused'))",
      "semanticType": "FeedbackType"
    },
    {
      "resultType": "error",
      "explanation": "HTTPConnectionPool(host='localhost', port=8083): Max retries exceeded with url: /api/semantic-types/generate (Caused by NewConnectionError('<urllib3.connection.HTTPConnection object at 0x1226d30d0>: Failed to establish a new connection: [Errno 61] Connection refused'))",
      "semanticType": "LoanType"
    },
    {
      "resultType": "error",
      "explanation": "HTTPConnectionPool(host='localhost', port=8083): Max retries exceeded with url: /api/semantic-types/generate (Caused by NewConnectionError('<urllib3.connection.HTTPConnection object at 0x1226d1f00>: Failed to establish a new connection: [Errno 61] Connection refused'))",
      "semanticType": "ResolutionStatus"
    },
    {
      "resultType": "error",
      "explanation": "HTTPConnectionPool(host='localhost', port=8083): Max retries exceeded with url: /api/semantic-types/generate (Caused by NewConnectionError('<urllib3.connection.HTTPConnection object at 0x122746680>: Failed to establish a new connection: [Errno 61] Connection refused'))",
      "semanticType": "InterestRate"
    }
  ]
}