{
  "dataset": "banking",
  "description_number": 5,
  "timestamp": "20250828_190549",
  "generated_types": [
    {
      "resultType": "error",
      "explanation": "HTTPConnectionPool(host='localhost', port=8083): Max retries exceeded with url: /api/semantic-types/generate (Caused by NewConnectionError('<urllib3.connection.HTTPConnection object at 0x128964f70>: Failed to establish a new connection: [Errno 61] Connection refused'))",
      "semanticType": "LoanAmount"
    },
    {
      "resultType": "error",
      "explanation": "HTTPConnectionPool(host='localhost', port=8083): Max retries exceeded with url: /api/semantic-types/generate (Caused by NewConnectionError('<urllib3.connection.HTTPConnection object at 0x12891c610>: Failed to establish a new connection: [Errno 61] Connection refused'))",
      "semanticType": "TransactionDate"
    },
    {
      "resultType": "error",
      "explanation": "HTTPConnectionPool(host='localhost', port=8083): Max retries exceeded with url: /api/semantic-types/generate (Caused by NewConnectionError('<urllib3.connection.HTTPConnection object at 0x128966a70>: Failed to establish a new connection: [Errno 61] Connection refused'))",
      "semanticType": "AccountBalanceAfterTransaction"
    },
    {
      "resultType": "error",
      "explanation": "HTTPConnectionPool(host='localhost', port=8083): Max retries exceeded with url: /api/semantic-types/generate (Caused by NewConnectionError('<urllib3.connection.HTTPConnection object at 0x12891dd20>: Failed to establish a new connection: [Errno 61] Connection refused'))",
      "semanticType": "TransactionAmount"
    },
    {
      "resultType": "error",
      "explanation": "HTTPConnectionPool(host='localhost', port=8083): Max retries exceeded with url: /api/semantic-types/generate (Caused by NewConnectionError('<urllib3.connection.HTTPConnection object at 0x12891d0f0>: Failed to establish a new connection: [Errno 61] Connection refused'))",
      "semanticType": "CreditLimit"
    },
    {
      "resultType": "error",
      "explanation": "HTTPConnectionPool(host='localhost', port=8083): Max retries exceeded with url: /api/semantic-types/generate (Caused by NewConnectionError('<urllib3.connection.HTTPConnection object at 0x128964b80>: Failed to establish a new connection: [Errno 61] Connection refused'))",
      "semanticType": "FeedbackType"
    },
    {
      "resultType": "error",
      "explanation": "HTTPConnectionPool(host='localhost', port=8083): Max retries exceeded with url: /api/semantic-types/generate (Caused by NewConnectionError('<urllib3.connection.HTTPConnection object at 0x1288b6e30>: Failed to establish a new connection: [Errno 61] Connection refused'))",
      "semanticType": "AccountBalance"
    },
    {
      "resultType": "error",
      "explanation": "HTTPConnectionPool(host='localhost', port=8083): Max retries exceeded with url: /api/semantic-types/generate (Caused by NewConnectionError('<urllib3.connection.HTTPConnection object at 0x1288b40d0>: Failed to establish a new connection: [Errno 61] Connection refused'))",
      "semanticType": "FeedbackID"
    },
    {
      "resultType": "error",
      "explanation": "HTTPConnectionPool(host='localhost', port=8083): Max retries exceeded with url: /api/semantic-types/generate (Caused by NewConnectionError('<urllib3.connection.HTTPConnection object at 0x1288195a0>: Failed to establish a new connection: [Errno 61] Connection refused'))",
      "semanticType": "LoanID"
    },
    {
      "resultType": "error",
      "explanation": "HTTPConnectionPool(host='localhost', port=8083): Max retries exceeded with url: /api/semantic-types/generate (Caused by NewConnectionError('<urllib3.connection.HTTPConnection object at 0x128966410>: Failed to establish a new connection: [Errno 61] Connection refused'))",
      "semanticType": "CardType"
    },
    {
      "resultType": "error",
      "explanation": "HTTPConnectionPool(host='localhost', port=8083): Max retries exceeded with url: /api/semantic-types/generate (Caused by NewConnectionError('<urllib3.connection.HTTPConnection object at 0x12891fd90>: Failed to establish a new connection: [Errno 61] Connection refused'))",
      "semanticType": "LoanType"
    },
    {
      "resultType": "error",
      "explanation": "HTTPConnectionPool(host='localhost', port=8083): Max retries exceeded with url: /api/semantic-types/generate (Caused by NewConnectionError('<urllib3.connection.HTTPConnection object at 0x128965cc0>: Failed to establish a new connection: [Errno 61] Connection refused'))",
      "semanticType": "LoanStatus"
    },
    {
      "resultType": "error",
      "explanation": "HTTPConnectionPool(host='localhost', port=8083): Max retries exceeded with url: /api/semantic-types/generate (Caused by NewConnectionError('<urllib3.connection.HTTPConnection object at 0x128964850>: Failed to establish a new connection: [Errno 61] Connection refused'))",
      "semanticType": "TransactionID"
    },
    {
      "resultType": "error",
      "explanation": "HTTPConnectionPool(host='localhost', port=8083): Max retries exceeded with url: /api/semantic-types/generate (Caused by NewConnectionError('<urllib3.connection.HTTPConnection object at 0x1288de710>: Failed to establish a new connection: [Errno 61] Connection refused'))",
      "semanticType": "ResolutionStatus"
    },
    {
      "resultType": "error",
      "explanation": "HTTPConnectionPool(host='localhost', port=8083): Max retries exceeded with url: /api/semantic-types/generate (Caused by NewConnectionError('<urllib3.connection.HTTPConnection object at 0x1288b73a0>: Failed to establish a new connection: [Errno 61] Connection refused'))",
      "semanticType": "BranchID"
    },
    {
      "resultType": "error",
      "explanation": "HTTPConnectionPool(host='localhost', port=8083): Max retries exceeded with url: /api/semantic-types/generate (Caused by NewConnectionError('<urllib3.connection.HTTPConnection object at 0x128967130>: Failed to establish a new connection: [Errno 61] Connection refused'))",
      "semanticType": "InterestRate"
    },
    {
      "resultType": "error",
      "explanation": "HTTPConnectionPool(host='localhost', port=8083): Max retries exceeded with url: /api/semantic-types/generate (Caused by NewConnectionError('<urllib3.connection.HTTPConnection object at 0x1288b5b10>: Failed to establish a new connection: [Errno 61] Connection refused'))",
      "semanticType": "AccountType"
    },
    {
      "resultType": "error",
      "explanation": "HTTPConnectionPool(host='localhost', port=8083): Max retries exceeded with url: /api/semantic-types/generate (Caused by NewConnectionError('<urllib3.connection.HTTPConnection object at 0x1288b68f0>: Failed to establish a new connection: [Errno 61] Connection refused'))",
      "semanticType": "AccountOpeningDate"
    }
  ]
}