{
  "dataset": "banking",
  "description_number": 2,
  "timestamp": "20250828_190549",
  "generated_types": [
    {
      "resultType": "error",
      "explanation": "HTTPConnectionPool(host='localhost', port=8083): Max retries exceeded with url: /api/semantic-types/generate (Caused by NewConnectionError('<urllib3.connection.HTTPConnection object at 0x1288b76d0>: Failed to establish a new connection: [Errno 61] Connection refused'))",
      "semanticType": "AccountBalanceAfterTransaction"
    },
    {
      "resultType": "error",
      "explanation": "HTTPConnectionPool(host='localhost', port=8083): Max retries exceeded with url: /api/semantic-types/generate (Caused by NewConnectionError('<urllib3.connection.HTTPConnection object at 0x12891dd20>: Failed to establish a new connection: [Errno 61] Connection refused'))",
      "semanticType": "CreditLimit"
    },
    {
      "resultType": "error",
      "explanation": "HTTPConnectionPool(host='localhost', port=8083): Max retries exceeded with url: /api/semantic-types/generate (Caused by NewConnectionError('<urllib3.connection.HTTPConnection object at 0x1288dde70>: Failed to establish a new connection: [Errno 61] Connection refused'))",
      "semanticType": "InterestRate"
    },
    {
      "resultType": "error",
      "explanation": "HTTPConnectionPool(host='localhost', port=8083): Max retries exceeded with url: /api/semantic-types/generate (Caused by NewConnectionError('<urllib3.connection.HTTPConnection object at 0x122689a50>: Failed to establish a new connection: [Errno 61] Connection refused'))",
      "semanticType": "TransactionAmount"
    },
    {
      "resultType": "error",
      "explanation": "HTTPConnectionPool(host='localhost', port=8083): Max retries exceeded with url: /api/semantic-types/generate (Caused by NewConnectionError('<urllib3.connection.HTTPConnection object at 0x1288b52d0>: Failed to establish a new connection: [Errno 61] Connection refused'))",
      "semanticType": "TransactionID"
    },
    {
      "resultType": "error",
      "explanation": "HTTPConnectionPool(host='localhost', port=8083): Max retries exceeded with url: /api/semantic-types/generate (Caused by NewConnectionError('<urllib3.connection.HTTPConnection object at 0x1288ddab0>: Failed to establish a new connection: [Errno 61] Connection refused'))",
      "semanticType": "AccountOpeningDate"
    },
    {
      "resultType": "error",
      "explanation": "HTTPConnectionPool(host='localhost', port=8083): Max retries exceeded with url: /api/semantic-types/generate (Caused by NewConnectionError('<urllib3.connection.HTTPConnection object at 0x1288de440>: Failed to establish a new connection: [Errno 61] Connection refused'))",
      "semanticType": "LoanAmount"
    },
    {
      "resultType": "error",
      "explanation": "HTTPConnectionPool(host='localhost', port=8083): Max retries exceeded with url: /api/semantic-types/generate (Caused by NewConnectionError('<urllib3.connection.HTTPConnection object at 0x12891c730>: Failed to establish a new connection: [Errno 61] Connection refused'))",
      "semanticType": "AccountType"
    },
    {
      "resultType": "error",
      "explanation": "HTTPConnectionPool(host='localhost', port=8083): Max retries exceeded with url: /api/semantic-types/generate (Caused by NewConnectionError('<urllib3.connection.HTTPConnection object at 0x12891e110>: Failed to establish a new connection: [Errno 61] Connection refused'))",
      "semanticType": "TransactionDate"
    },
    {
      "resultType": "error",
      "explanation": "HTTPConnectionPool(host='localhost', port=8083): Max retries exceeded with url: /api/semantic-types/generate (Caused by NewConnectionError('<urllib3.connection.HTTPConnection object at 0x12891e890>: Failed to establish a new connection: [Errno 61] Connection refused'))",
      "semanticType": "ResolutionStatus"
    },
    {
      "resultType": "error",
      "explanation": "HTTPConnectionPool(host='localhost', port=8083): Max retries exceeded with url: /api/semantic-types/generate (Caused by NewConnectionError('<urllib3.connection.HTTPConnection object at 0x12881b310>: Failed to establish a new connection: [Errno 61] Connection refused'))",
      "semanticType": "LoanType"
    },
    {
      "resultType": "error",
      "explanation": "HTTPConnectionPool(host='localhost', port=8083): Max retries exceeded with url: /api/semantic-types/generate (Caused by NewConnectionError('<urllib3.connection.HTTPConnection object at 0x12891d960>: Failed to establish a new connection: [Errno 61] Connection refused'))",
      "semanticType": "CardType"
    },
    {
      "resultType": "error",
      "explanation": "HTTPConnectionPool(host='localhost', port=8083): Max retries exceeded with url: /api/semantic-types/generate (Caused by NewConnectionError('<urllib3.connection.HTTPConnection object at 0x1288b4f10>: Failed to establish a new connection: [Errno 61] Connection refused'))",
      "semanticType": "BranchID"
    },
    {
      "resultType": "error",
      "explanation": "HTTPConnectionPool(host='localhost', port=8083): Max retries exceeded with url: /api/semantic-types/generate (Caused by NewConnectionError('<urllib3.connection.HTTPConnection object at 0x1288dfcd0>: Failed to establish a new connection: [Errno 61] Connection refused'))",
      "semanticType": "LoanStatus"
    },
    {
      "resultType": "error",
      "explanation": "HTTPConnectionPool(host='localhost', port=8083): Max retries exceeded with url: /api/semantic-types/generate (Caused by NewConnectionError('<urllib3.connection.HTTPConnection object at 0x1288dd6f0>: Failed to establish a new connection: [Errno 61] Connection refused'))",
      "semanticType": "AccountBalance"
    },
    {
      "resultType": "error",
      "explanation": "HTTPConnectionPool(host='localhost', port=8083): Max retries exceeded with url: /api/semantic-types/generate (Caused by NewConnectionError('<urllib3.connection.HTTPConnection object at 0x12891ef80>: Failed to establish a new connection: [Errno 61] Connection refused'))",
      "semanticType": "LoanID"
    },
    {
      "resultType": "error",
      "explanation": "HTTPConnectionPool(host='localhost', port=8083): Max retries exceeded with url: /api/semantic-types/generate (Caused by NewConnectionError('<urllib3.connection.HTTPConnection object at 0x1288df910>: Failed to establish a new connection: [Errno 61] Connection refused'))",
      "semanticType": "FeedbackType"
    },
    {
      "resultType": "error",
      "explanation": "HTTPConnectionPool(host='localhost', port=8083): Max retries exceeded with url: /api/semantic-types/generate (Caused by NewConnectionError('<urllib3.connection.HTTPConnection object at 0x12891fa30>: Failed to establish a new connection: [Errno 61] Connection refused'))",
      "semanticType": "FeedbackID"
    }
  ]
}