{
  "dataset": "banking",
  "description_number": 4,
  "timestamp": "20250828_190549",
  "generated_types": [
    {
      "resultType": "error",
      "explanation": "HTTPConnectionPool(host='localhost', port=8083): Max retries exceeded with url: /api/semantic-types/generate (Caused by NewConnectionError('<urllib3.connection.HTTPConnection object at 0x12891ca90>: Failed to establish a new connection: [Errno 61] Connection refused'))",
      "semanticType": "AccountBalance"
    },
    {
      "resultType": "error",
      "explanation": "HTTPConnectionPool(host='localhost', port=8083): Max retries exceeded with url: /api/semantic-types/generate (Caused by NewConnectionError('<urllib3.connection.HTTPConnection object at 0x1288defb0>: Failed to establish a new connection: [Errno 61] Connection refused'))",
      "semanticType": "TransactionAmount"
    },
    {
      "resultType": "error",
      "explanation": "HTTPConnectionPool(host='localhost', port=8083): Max retries exceeded with url: /api/semantic-types/generate (Caused by NewConnectionError('<urllib3.connection.HTTPConnection object at 0x12264eb00>: Failed to establish a new connection: [Errno 61] Connection refused'))",
      "semanticType": "TransactionDate"
    },
    {
      "resultType": "error",
      "explanation": "HTTPConnectionPool(host='localhost', port=8083): Max retries exceeded with url: /api/semantic-types/generate (Caused by NewConnectionError('<urllib3.connection.HTTPConnection object at 0x12891c370>: Failed to establish a new connection: [Errno 61] Connection refused'))",
      "semanticType": "TransactionID"
    },
    {
      "resultType": "error",
      "explanation": "HTTPConnectionPool(host='localhost', port=8083): Max retries exceeded with url: /api/semantic-types/generate (Caused by NewConnectionError('<urllib3.connection.HTTPConnection object at 0x128819420>: Failed to establish a new connection: [Errno 61] Connection refused'))",
      "semanticType": "AccountOpeningDate"
    },
    {
      "resultType": "error",
      "explanation": "HTTPConnectionPool(host='localhost', port=8083): Max retries exceeded with url: /api/semantic-types/generate (Caused by NewConnectionError('<urllib3.connection.HTTPConnection object at 0x128964190>: Failed to establish a new connection: [Errno 61] Connection refused'))",
      "semanticType": "BranchID"
    },
    {
      "resultType": "error",
      "explanation": "HTTPConnectionPool(host='localhost', port=8083): Max retries exceeded with url: /api/semantic-types/generate (Caused by NewConnectionError('<urllib3.connection.HTTPConnection object at 0x128966d70>: Failed to establish a new connection: [Errno 61] Connection refused'))",
      "semanticType": "InterestRate"
    },
    {
      "resultType": "error",
      "explanation": "HTTPConnectionPool(host='localhost', port=8083): Max retries exceeded with url: /api/semantic-types/generate (Caused by NewConnectionError('<urllib3.connection.HTTPConnection object at 0x12891c0d0>: Failed to establish a new connection: [Errno 61] Connection refused'))",
      "semanticType": "LoanStatus"
    },
    {
      "resultType": "error",
      "explanation": "HTTPConnectionPool(host='localhost', port=8083): Max retries exceeded with url: /api/semantic-types/generate (Caused by NewConnectionError('<urllib3.connection.HTTPConnection object at 0x12268b2b0>: Failed to establish a new connection: [Errno 61] Connection refused'))",
      "semanticType": "LoanAmount"
    },
    {
      "resultType": "error",
      "explanation": "HTTPConnectionPool(host='localhost', port=8083): Max retries exceeded with url: /api/semantic-types/generate (Caused by NewConnectionError('<urllib3.connection.HTTPConnection object at 0x128967400>: Failed to establish a new connection: [Errno 61] Connection refused'))",
      "semanticType": "LoanType"
    },
    {
      "resultType": "error",
      "explanation": "HTTPConnectionPool(host='localhost', port=8083): Max retries exceeded with url: /api/semantic-types/generate (Caused by NewConnectionError('<urllib3.connection.HTTPConnection object at 0x128964550>: Failed to establish a new connection: [Errno 61] Connection refused'))",
      "semanticType": "CardType"
    },
    {
      "resultType": "error",
      "explanation": "HTTPConnectionPool(host='localhost', port=8083): Max retries exceeded with url: /api/semantic-types/generate (Caused by NewConnectionError('<urllib3.connection.HTTPConnection object at 0x128965330>: Failed to establish a new connection: [Errno 61] Connection refused'))",
      "semanticType": "AccountType"
    },
    {
      "resultType": "error",
      "explanation": "HTTPConnectionPool(host='localhost', port=8083): Max retries exceeded with url: /api/semantic-types/generate (Caused by NewConnectionError('<urllib3.connection.HTTPConnection object at 0x12891e890>: Failed to establish a new connection: [Errno 61] Connection refused'))",
      "semanticType": "FeedbackType"
    },
    {
      "resultType": "error",
      "explanation": "HTTPConnectionPool(host='localhost', port=8083): Max retries exceeded with url: /api/semantic-types/generate (Caused by NewConnectionError('<urllib3.connection.HTTPConnection object at 0x1288b56f0>: Failed to establish a new connection: [Errno 61] Connection refused'))",
      "semanticType": "ResolutionStatus"
    },
    {
      "resultType": "error",
      "explanation": "HTTPConnectionPool(host='localhost', port=8083): Max retries exceeded with url: /api/semantic-types/generate (Caused by NewConnectionError('<urllib3.connection.HTTPConnection object at 0x1288b66e0>: Failed to establish a new connection: [Errno 61] Connection refused'))",
      "semanticType": "FeedbackID"
    },
    {
      "resultType": "error",
      "explanation": "HTTPConnectionPool(host='localhost', port=8083): Max retries exceeded with url: /api/semantic-types/generate (Caused by NewConnectionError('<urllib3.connection.HTTPConnection object at 0x1289667d0>: Failed to establish a new connection: [Errno 61] Connection refused'))",
      "semanticType": "LoanID"
    },
    {
      "resultType": "error",
      "explanation": "HTTPConnectionPool(host='localhost', port=8083): Max retries exceeded with url: /api/semantic-types/generate (Caused by NewConnectionError('<urllib3.connection.HTTPConnection object at 0x1288b6800>: Failed to establish a new connection: [Errno 61] Connection refused'))",
      "semanticType": "CreditLimit"
    },
    {
      "resultType": "error",
      "explanation": "HTTPConnectionPool(host='localhost', port=8083): Max retries exceeded with url: /api/semantic-types/generate (Caused by NewConnectionError('<urllib3.connection.HTTPConnection object at 0x128965900>: Failed to establish a new connection: [Errno 61] Connection refused'))",
      "semanticType": "AccountBalanceAfterTransaction"
    }
  ]
}